<?xml version="1.0"?>

<robot name="example_urdf">
    <link name="base">
    </link>

    <joint name="base-base_1-joint" type="fixed">
        <origin xyz="0 0 0" rpy="0 0 0"/>
        <parent link="base"/>
        <child link="base_1"/>
    </joint>

    <joint name="base-base_2-joint" type="fixed">
        <origin xyz="0 1 0" rpy="0 0 0"/>
        <parent link="base"/>
        <child link="base_2"/>
    </joint>

    <link name="base_1">
        <inertial>
            <origin xyz="0 0 0.25" rpy="0 0 0"/>
            <mass value="1"/>
            <inertia ixx="0.063" ixy="0" ixz="0" iyy="0.063" iyz="0" izz="0.125"/>
        </inertial>

        <visual>
            <origin xyz="0 0 0.25" rpy="0 0 0"/>
            <geometry>
                <cylinder radius="0.1" length="0.5"/>
            </geometry>
            <material name="gray">
                <color rgba="0.1 0.1 0.1 1.0"/>
            </material>
        </visual>
    </link>

    <joint name="1_body_1-base-joint" type="revolute">
        <origin xyz="0 0 0.5" rpy="0 0 0"/>
        <parent link="base_1"/>
        <child link="1_body_1"/>
        <axis xyz="0 0 1"/>
        <limit effort="30" velocity="1.0" lower="-3.14159" upper="3.14159"/>
    </joint>

    <link name="1_body_1">
        <inertial>
            <origin xyz="0 0.1 0.1" rpy="-0.7853982 0 0"/>
            <mass value="1"/>
            <inertia ixx="0.021" ixy="0" ixz="0" iyy="0.021" iyz="0" izz="0.040"/>
        </inertial>

        <visual>
            <origin xyz="0 0.1 0.1" rpy="-0.7853982 0 0"/>
            <geometry>
                <cylinder radius="0.1" length="0.2828"/>
            </geometry>
            <material name="gray"></material>
        </visual>
    </link>

    <joint name="1_body_2-body_1-joint" type="revolute">
        <origin xyz="0 0.2 0.2" rpy="0.7853982 0 0"/>
        <parent link="1_body_1"/>
        <child link="1_body_2"/>
        <axis xyz="0 1 0"/>
        <limit effort="30" velocity="1.0" lower="-3.14159" upper="3.14159"/>
    </joint>

    <link name="1_body_2">
        <inertial>
            <origin xyz="0 0 0.1" rpy="0 0 0"/>
            <mass value="1"/>
            <inertia ixx="0.021" ixy="0" ixz="0" iyy="0.021" iyz="0" izz="0.040"/>
        </inertial>

        <visual>
            <origin xyz="0 0 0.1" rpy="0 0 0"/>
            <geometry>
                <cylinder radius="0.1" length="0.2828"/>
            </geometry>
            <material name="gray"></material>
        </visual>
    </link>

    <joint name="1_body_3-body_2-joint" type="revolute">
        <origin xyz="0 0 0.2828" rpy="-1.5707963 0.7853981 -1.5707963"/>
        <parent link="1_body_2"/>
        <child link="1_body_3"/>
        <axis xyz="0 0 1"/>
        <limit effort="30" velocity="1.0" lower="-3.14159" upper="3.14159"/>
    </joint>

    <link name="1_body_3">
        <inertial>
            <origin xyz="0 0 0.15" rpy="0 0 0"/>
            <mass value="1"/>
            <inertia ixx="0.023" ixy="0" ixz="0" iyy="0.023" iyz="0" izz="0.045"/>
        </inertial>

        <visual>
            <origin xyz="0 0 0.15" rpy="0 0 0"/>
            <geometry>
                <cylinder radius="0.1" length="0.3"/>
            </geometry>
            <material name="gray"></material>
        </visual>
    </link>

    <joint name="1_body_4-body_3-joint" type="revolute">
        <origin xyz="0 0 0.3" rpy="0 -1.5707963 0"/>
        <parent link="1_body_3"/>
        <child link="1_body_4"/>
        <axis xyz="0 0 1"/>
        <limit effort="30" velocity="1.0" lower="-3.14159" upper="3.14159"/>
    </joint>

    <link name="1_body_4">
        <inertial>
            <origin xyz="0 0 0.15" rpy="0 0 0"/>
            <mass value="1"/>
            <inertia ixx="0.023" ixy="0" ixz="0" iyy="0.023" iyz="0" izz="0.045"/>
        </inertial>

        <visual>
            <origin xyz="0 0 0.15" rpy="0 0 0"/>
            <geometry>
                <cylinder radius="0.1" length="0.3"/>
            </geometry>
            <material name="gray"></material>
        </visual>
    </link>

    <joint name="1_body_5-body_4-joint" type="revolute">
        <origin xyz="0 0 0.3" rpy="0 -1.5707963 0"/>
        <parent link="1_body_4"/>
        <child link="1_body_5"/>
        <axis xyz="0 1 0"/>
        <limit effort="30" velocity="1.0" lower="-3.14159" upper="3.14159"/>
    </joint>

    <link name="1_body_5">
        <inertial>
            <origin xyz="0 0 0.15" rpy="0 0 0"/>
            <mass value="1"/>
            <inertia ixx="0.023" ixy="0" ixz="0" iyy="0.023" iyz="0" izz="0.045"/>
        </inertial>

        <visual>
            <origin xyz="0 0 0.15" rpy="0 0 0"/>
            <geometry>
                <cylinder radius="0.1" length="0.3"/>
            </geometry>
            <material name="gray"></material>
        </visual>
    </link>

    <joint name="1_gripper-body_5-joint" type="revolute">
        <origin xyz="0 0 0.3" rpy="0 0 0"/>
        <parent link="1_body_5"/>
        <child link="1_gripper"/>
        <axis xyz="0 1 0"/>
        <limit effort="30" velocity="1.0" lower="-3.14159" upper="3.14159"/>
    </joint>

    <link name="1_gripper">
        <inertial>
            <origin xyz="0.15 0 0" rpy="0 1.5707963 0"/>
            <mass value="0.1"/>
            <inertia ixx="0.0023" ixy="0" ixz="0" iyy="0.0023" iyz="0" izz="0.0045"/>
        </inertial>

        <visual>
            <origin xyz="0.15 0 0" rpy="0 1.5707963 0"/>
            <geometry>
                <cylinder radius="0.05" length="0.1"/>
            </geometry>
            <material name="gray"></material>
        </visual>
    </link>

    <link name="base_2">
        <inertial>
            <origin xyz="0 0 0.25" rpy="0 0 0"/>
            <mass value="1"/>
            <inertia ixx="0.063" ixy="0" ixz="0" iyy="0.063" iyz="0" izz="0.125"/>
        </inertial>

        <visual>
            <origin xyz="0 0 0.25" rpy="0 0 0"/>
            <geometry>
                <cylinder radius="0.1" length="0.5"/>
            </geometry>
            <material name="gray">
                <color rgba="0.1 0.1 0.1 1.0"/>
            </material>
        </visual>
    </link>

    <joint name="2_body_1-base-joint" type="revolute">
        <origin xyz="0 0 0.5" rpy="0 0 0"/>
        <parent link="base_2"/>
        <child link="2_body_1"/>
        <axis xyz="0 0 1"/>
        <limit effort="30" velocity="1.0" lower="-3.14159" upper="3.14159"/>
    </joint>

    <link name="2_body_1">
        <inertial>
            <origin xyz="0 0.1 0.1" rpy="-0.7853982 0 0"/>
            <mass value="1"/>
            <inertia ixx="0.021" ixy="0" ixz="0" iyy="0.021" iyz="0" izz="0.040"/>
        </inertial>

        <visual>
            <origin xyz="0 0.1 0.1" rpy="-0.7853982 0 0"/>
            <geometry>
                <cylinder radius="0.1" length="0.2828"/>
            </geometry>
            <material name="gray"></material>
        </visual>
    </link>

    <joint name="2_body_2-body_1-joint" type="revolute">
        <origin xyz="0 0.2 0.2" rpy="0.7853982 0 0"/>
        <parent link="2_body_1"/>
        <child link="2_body_2"/>
        <axis xyz="0 1 0"/>
        <limit effort="30" velocity="1.0" lower="-3.14159" upper="3.14159"/>
    </joint>

    <link name="2_body_2">
        <inertial>
            <origin xyz="0 0 0.1" rpy="0 0 0"/>
            <mass value="1"/>
            <inertia ixx="0.021" ixy="0" ixz="0" iyy="0.021" iyz="0" izz="0.040"/>
        </inertial>

        <visual>
            <origin xyz="0 0 0.1" rpy="0 0 0"/>
            <geometry>
                <cylinder radius="0.1" length="0.2828"/>
            </geometry>
            <material name="gray"></material>
        </visual>
    </link>

    <joint name="2_body_3-body_2-joint" type="revolute">
        <origin xyz="0 0 0.2828" rpy="-1.5707963 0.7853981 -1.5707963"/>
        <parent link="2_body_2"/>
        <child link="2_body_3"/>
        <axis xyz="0 0 1"/>
        <limit effort="30" velocity="1.0" lower="-3.14159" upper="3.14159"/>
    </joint>

    <link name="2_body_3">
        <inertial>
            <origin xyz="0 0 0.15" rpy="0 0 0"/>
            <mass value="1"/>
            <inertia ixx="0.023" ixy="0" ixz="0" iyy="0.023" iyz="0" izz="0.045"/>
        </inertial>

        <visual>
            <origin xyz="0 0 0.15" rpy="0 0 0"/>
            <geometry>
                <cylinder radius="0.1" length="0.3"/>
            </geometry>
            <material name="gray"></material>
        </visual>
    </link>

    <joint name="2_body_4-body_3-joint" type="revolute">
        <origin xyz="0 0 0.3" rpy="0 -1.5707963 0"/>
        <parent link="2_body_3"/>
        <child link="2_body_4"/>
        <axis xyz="0 0 1"/>
        <limit effort="30" velocity="1.0" lower="-3.14159" upper="3.14159"/>
    </joint>

    <link name="2_body_4">
        <inertial>
            <origin xyz="0 0 0.15" rpy="0 0 0"/>
            <mass value="1"/>
            <inertia ixx="0.023" ixy="0" ixz="0" iyy="0.023" iyz="0" izz="0.045"/>
        </inertial>

        <visual>
            <origin xyz="0 0 0.15" rpy="0 0 0"/>
            <geometry>
                <cylinder radius="0.1" length="0.3"/>
            </geometry>
            <material name="gray"></material>
        </visual>
    </link>

    <joint name="2_body_5-body_4-joint" type="revolute">
        <origin xyz="0 0 0.3" rpy="0 -1.5707963 0"/>
        <parent link="2_body_4"/>
        <child link="2_body_5"/>
        <axis xyz="0 1 0"/>
        <limit effort="30" velocity="1.0" lower="-3.14159" upper="3.14159"/>
    </joint>

    <link name="2_body_5">
        <inertial>
            <origin xyz="0 0 0.15" rpy="0 0 0"/>
            <mass value="1"/>
            <inertia ixx="0.023" ixy="0" ixz="0" iyy="0.023" iyz="0" izz="0.045"/>
        </inertial>

        <visual>
            <origin xyz="0 0 0.15" rpy="0 0 0"/>
            <geometry>
                <cylinder radius="0.1" length="0.3"/>
            </geometry>
            <material name="gray"></material>
        </visual>
    </link>

    <joint name="2_gripper-body_5-joint" type="revolute">
        <origin xyz="0 0 0.3" rpy="0 0 0"/>
        <parent link="2_body_5"/>
        <child link="2_gripper"/>
        <axis xyz="0 1 0"/>
        <limit effort="30" velocity="1.0" lower="-3.14159" upper="3.14159"/>
    </joint>

    <link name="2_gripper">
        <inertial>
            <origin xyz="0.15 0 0" rpy="0 1.5707963 0"/>
            <mass value="0.1"/>
            <inertia ixx="0.0023" ixy="0" ixz="0" iyy="0.0023" iyz="0" izz="0.0045"/>
        </inertial>

        <visual>
            <origin xyz="0.15 0 0" rpy="0 1.5707963 0"/>
            <geometry>
                <cylinder radius="0.05" length="0.1"/>
            </geometry>
            <material name="gray"></material>
        </visual>
    </link>
</robot>
