<mujoco>
  <option gravity="0 0 -10" timestep="0.001">
  </option>

  <default>
    <geom rgba=".9 .0 .0 1"/>
  </default>

  <worldbody>
    <light pos="100 0 0" dir="-1 0 0" diffuse="1 1 1" cutoff="180"/>
    <site type="sphere" size="0.05" name="origin"/>

    <body pos="0 0 0" euler="60 0 0">
      <geom type="sphere" size="0.05" mass="1" pos="0 1 0"/>
      <site type="cylinder" size="0.01 0.5" pos="0 0.5 0" euler="90 0 0"/>
      <joint type="hinge" axis="1 0 0" pos="0 0 0"/>

      <body pos="0 1 0" euler="-120 0 0">
        <geom type="sphere" size="0.05" mass="1" pos="0 1 0"/>
        <site type="sphere" size="0.01" name="second"/>
        <site type="cylinder" size="0.01 0.5" pos="0 0.5 0" euler="90 0 0"/>
        <joint type="hinge" axis="1 0 0" pos="0 0 0"/>
      </body>
    </body>
  </worldbody>
</mujoco>
