<mujoco model="example_mjcf">
  <compiler angle="radian" eulerseq="xyz"/>
  <option integrator="RK4" gravity="0 0 -9.81" timestep="0.001"/>

  <worldbody>
    <body name="base">
      <inertial mass="1.0" pos="0 0 0.25" diaginertia="0.063 0.063 0.125"/>
      <site type="cylinder" pos="0 0 0.25" size="0.1 0.25"/>

      <body name="body_1" pos="0 0 0.5">
        <inertial pos="0 0.1 0.1" mass="1.0" diaginertia="0.021 0.021 0.040" euler="-0.7853982 0 0"/>
        <site type="cylinder" pos="0 0.1 0.1" size="0.1 0.1414" euler="-0.7853982 0 0"/>
        <joint name="body_1-base-joint" axis="0 0 1" limited="true" range="-3.14159 3.14159"/>

        <body name="body_2" pos="0 0.2 0.2" euler="0.7853982 0 0">
          <inertial pos="0 0 0.1" mass="1.0" diaginertia="0.021 0.021 0.040"/>
          <site type="cylinder" pos="0 0 0.1" size="0.1 0.1414"/>
          <joint name="body_2-body_1-joint" axis="0 1 0" limited="true" range="-3.14159 3.14159"/>

          <body name="body_3" pos="0 0 0.2828" euler="-0.7853982 1.5707963 0">
            <inertial pos="0 0 0.15" mass="1.0" diaginertia="0.023 0.023 0.045"/>
            <site type="cylinder" pos="0 0 0.15" size="0.1 0.15"/>
            <joint name="body_3-body_2-joint" axis="0 0 1" limited="true" range="-3.14159 3.14159"/>

            <body name="body_4" pos="0 0 0.3" euler="0 -1.5707963 0">
              <inertial pos="0 0 0.15" mass="1.0" diaginertia="0.023 0.023 0.045"/>
              <site type="cylinder" pos="0 0 0.15" size="0.1 0.15"/>
              <joint name="body_4-body_3-joint" axis="0 0 1" limited="true" range="-3.14159 3.14159"/>

              <body name="body_5" pos="0 0 0.3" euler="0 -1.5707963 0">
                <inertial pos="0 0 0.15" mass="1.0" diaginertia="0.023 0.023 0.045"/>
                <site type="cylinder" pos="0 0 0.15" size="0.1 0.15"/>
                <joint name="body_5-body_4-joint" axis="0 1 0" limited="true" range="-3.14159 3.14159"/>

                <body name="gripper" pos="0 0 0.3" euler="0 0 0">
                  <inertial pos="0.15 0 0" mass="0.1" diaginertia="0.0023 0.0023 0.0045" euler="0 1.5707963 0"/>
                  <site type="cylinder" pos="0.15 0 0" size="0.05 0.05" euler="0 1.5707963 0"/>
                  <joint name="gripper-body_5-joint" axis="0 1 0" limited="true" range="-3.14159 3.14159"/>
                </body>
              </body>
            </body>
          </body>
        </body>
      </body>
    </body>
  </worldbody>
</mujoco>
